<?xml version="1.0" ?>
<robot xmlns:xacro="http://ros.org/wiki/xacro">
	<xacro:macro name="motoman_arm" params="prefix">
		<!-- link list -->
		<link name="${prefix}base_link">
			<visual>
				<origin rpy="0 0 0" xyz="0 0 0"/>
				<geometry>
					<mesh filename="package://motoman_mh6full_support/meshes/mh6full/visual/base.stl" />
				</geometry>
				<material name="blue">
					<color rgba="0.8 0.8 0.8 1"/>
				</material>
			</visual>
			<collision>
				<origin rpy="0 0 0" xyz="0 0 0"/>
				<geometry>
					<mesh filename="package://motoman_mh6full_support/meshes/mh6full/collision/base.stl" />
				</geometry>
				<material name="yellow"/>
			</collision>
		</link>
		<link name="${prefix}link_s">
			<visual>
				<origin rpy="0 0 0" xyz="0 0 0"/>
				<geometry>
					<mesh filename="package://motoman_mh6full_support/meshes/mh6full/visual/ejeS.stl"/>
				</geometry>
				<material name="silver"/>
			</visual>
			<collision>
				<origin rpy="0 0 0" xyz="0 0 0"/>
				<geometry>
					<mesh filename="package://motoman_mh6full_support/meshes/mh6full/collision/ejeS.stl" />
				</geometry>
				<material name="yellow"/>
			</collision>
		</link>
		<link name="${prefix}link_l">
			<visual>
				<origin rpy="0 0 0" xyz="0 0 0"/>
				<geometry>
					<mesh filename="package://motoman_mh6full_support/meshes/mh6full/visual/ejeL.stl"/>
				</geometry>
				<material name="blue"/>
			</visual>
			<collision>
				<origin rpy="0 0 0" xyz="0 0 0"/>
				<geometry>
					<mesh filename="package://motoman_mh6full_support/meshes/mh6full/collision/ejeL.stl" />
				</geometry>
				<material name="yellow"/>
			</collision>
		</link>
		<link name="${prefix}link_u">
			<visual>
				<origin rpy="0 0 0" xyz="0 0 0"/>
				<geometry>
					<mesh filename="package://motoman_mh6full_support/meshes/mh6full/visual/ejeU.stl"/>
				</geometry>
				<material name="blue"/>
			</visual>
			<collision>
				<origin rpy="0 0 0" xyz="0 0 0"/>
				<geometry>
					<mesh filename="package://motoman_mh6full_support/meshes/mh6full/collision/ejeU.stl" />
				</geometry>
				<material name="yellow"/>
			</collision>
		</link>
		<link name="${prefix}link_r">
			<visual>
				<origin rpy="0 0 0" xyz="0 0 0"/>
				<geometry>
					<mesh filename="package://motoman_mh6full_support/meshes/mh6full/visual/ejeR.stl"/>
				</geometry>
				<material name="silver"/>
			</visual>
			<collision>
				<origin rpy="0 0 0" xyz="0 0 0"/>
				<geometry>
					<mesh filename="package://motoman_mh6full_support/meshes/mh6full/collision/ejeR.stl" />
				</geometry>
				<material name="yellow"/>
			</collision>
		</link>
		<link name="${prefix}link_b">
			<visual>
				<origin rpy="0 0 0" xyz="0 0 0"/>
				<geometry>
					<mesh filename="package://motoman_mh6full_support/meshes/mh6full/visual/ejeB.stl"/>
				</geometry>
				<material name="blue"/>
			</visual>
			<collision>
				<origin rpy="0 0 0" xyz="0 0 0"/>
				<geometry>
					<mesh filename="package://motoman_mh6full_support/meshes/mh6full/collision/ejeB.stl" />
				</geometry>
				<material name="yellow"/>
			</collision>
		</link>
		<link name="${prefix}link_t">
			<visual>
				<geometry>
					<mesh filename="package://motoman_mh6full_support/meshes/mh6full/visual/ejeT.stl" />
				</geometry>
				<material name="silver"/>
			</visual>
			<collision>
				<geometry>
					<mesh filename="package://motoman_mh6full_support/meshes/mh6full/collision/ejeT.stl" />
				</geometry>
				<material name="yellow"/>
			</collision>
		</link>

		<link name="${prefix}link_tool0" />

		<!-- end of link list -->

		<!-- joint list -->
		<joint name="${prefix}joint_s" type="revolute">
			<parent link="${prefix}base_link"/>
			<child link="${prefix}link_s"/>
			<origin xyz="0 0 0.1680" rpy="0 0 0"/>
			<axis xyz="0 0 1" />
			<limit lower="-2.9671" upper="2.9671" effort="0" velocity="2.96" />
		</joint>
		<joint name="${prefix}joint_l" type="revolute">
			<parent link="${prefix}link_s"/>
			<child link="${prefix}link_l"/>
			<origin xyz="0.1500 0 0.2820" rpy="0 0 0"/>
			<axis xyz="0 1 0" />
			<limit lower="-1.5708" upper="2.7053" effort="0" velocity="2.96" />
		</joint>
		<joint name="${prefix}joint_u" type="revolute">
			<parent link="${prefix}link_l"/>
			<child link="${prefix}link_u"/>
			<origin xyz="0 0 0.6140" rpy="0 0 0"/>
			<axis xyz="0 -1 0" />
			<!-- <limit lower="-3.0543" upper="4.3633" effort="0" velocity="2.96" /> -->
			<limit lower="-3.0543" upper="2.2689" effort="0" velocity="2.96" />
		</joint>
		<joint name="${prefix}joint_r" type="revolute">
			<parent link="${prefix}link_u"/>
			<child link="${prefix}link_r"/>
			<origin xyz="0.2180 0 0.1550" rpy="0 0 0"/>
			<axis xyz="-1 0 0" />
			<!-- <limit lower="-3.1416" upper="3.1416" effort="0" velocity="3.48" /> -->
			<limit lower="-3.05" upper="3.05" effort="0" velocity="3.48" />
		</joint>
		<joint name="${prefix}joint_b" type="revolute">
			<parent link="${prefix}link_r"/>
			<child link="${prefix}link_b"/>
			<origin xyz="0.4220 0 0" rpy="0 0 0"/>
			<axis xyz="0 -1 0" />
			<!-- <limit lower="-0.7854" upper="3.927" effort="0" velocity="3.48" /> -->
			<limit lower="-0.5235" upper="3.2637" effort="0" velocity="3.48" />
		</joint>
		<joint name="${prefix}joint_t" type="revolute">
			<parent link="${prefix}link_b"/>
			<child link="${prefix}link_t"/>
			<origin xyz="0 0 -0.095" rpy="0 0 0"/>
			<axis xyz="0 0 1" />
			<limit lower="-6.2831" upper="6.2831" effort="0" velocity="6.97" />
		</joint>

		<joint name="${prefix}joint_tool0" type="fixed" >
			<!-- <origin xyz="0.014929 0.005989 -0.445411" rpy="0 -3.14 0"/> mototool -->
			<!-- origin xyz="0 0 -0.18" rpy="0 -3.14 -3.14"/> gripper -->
			<origin xyz="0 0 -0.18" rpy="0 -3.14 -3.14"/>
			<parent link="${prefix}link_t" />
			<child link="${prefix}link_tool0" />
		</joint>


		<!-- end of joint list -->
	</xacro:macro>
</robot>

