<?xml version="1.0" ?>
<robot xmlns:xacro="http://ros.org/wiki/xacro">
	<xacro:macro name="motoman_base" params="prefix">
		<!-- link list -->
		<link name="${prefix}rail_link">
			<visual>
				<origin rpy="0 0 0" xyz="0 0 0.029"/>
				<geometry>
					<mesh filename="package://motoman_mh6full_support/meshes/mh6full/visual/rail_base.stl" />
				</geometry>
				<material name="blue">
					<color rgba="0 0 1 1"/>
				</material>
			</visual>
			<collision>
				<origin rpy="0 0 0" xyz="0 0 0.029"/>
				<geometry>
					<mesh filename="package://motoman_mh6full_support/meshes/mh6full/collision/rail_base.stl" />
				</geometry>
				<material name="yellow">
					<color rgba="0 1 1 1"/>
				</material>
			</collision>
		</link>
		<link name="${prefix}link_b1">
			<visual>
				<origin rpy="0 0 0" xyz="0 0 0.029"/>
				<geometry>
					<mesh filename="package://motoman_mh6full_support/meshes/mh6full/visual/motoman_axis_b1.stl"/>
				</geometry>
				<material name="silver">
					<color rgba="0.8 0.8 0.8 1"/>
				</material>
			</visual>
			<collision>
				<origin rpy="0 0 0" xyz="0 0 0.029"/>
				<geometry>
					<mesh filename="package://motoman_mh6full_support/meshes/mh6full/collision/motoman_axis_b1.stl"/>
				</geometry>
				<material name="yellow"/>
			</collision>
		</link>

		<!-- joint list -->
		<joint name="${prefix}joint_b1" type="prismatic">
			<parent link="${prefix}rail_link"/>
			<child link="${prefix}link_b1"/>
			<origin xyz="2.0 0 0.205" rpy="0 0 0"/>
			<axis xyz="1 0 0" />
			<limit lower="-1.499" upper="1.499" effort="0" velocity="1.8" />
		</joint>
		<!-- end of joint list -->
	</xacro:macro>
</robot>
